INFO:werkzeug:127.0.0.1 - - [19/Apr/2021 11:31:34] "[37mGET / HTTP/1.1[0m" 200 -
INFO:werkzeug:127.0.0.1 - - [19/Apr/2021 11:31:34] "[37mGET /static/sms4_43518.png HTTP/1.1[0m" 200 -
INFO:werkzeug:127.0.0.1 - - [19/Apr/2021 11:31:36] "[37mGET /static/sms4_43518.ico HTTP/1.1[0m" 200 -
INFO:werkzeug:127.0.0.1 - - [19/Apr/2021 11:31:37] "[37mGET /login HTTP/1.1[0m" 200 -
INFO:werkzeug:127.0.0.1 - - [19/Apr/2021 11:31:45] "[32mPOST /login HTTP/1.1[0m" 302 -
WARNING:googleapiclient.discovery_cache:file_cache is unavailable when using oauth2client >= 4.0.0 or google-auth
Traceback (most recent call last):
  File "c:\users\user\appdata\local\programs\python\python37\lib\site-packages\googleapiclient\discovery_cache\file_cache.py", line 33, in <module>
    from oauth2client.contrib.locked_file import LockedFile
ModuleNotFoundError: No module named 'oauth2client'

During handling of the above exception, another exception occurred:

Traceback (most recent call last):
  File "c:\users\user\appdata\local\programs\python\python37\lib\site-packages\googleapiclient\discovery_cache\file_cache.py", line 37, in <module>
    from oauth2client.locked_file import LockedFile
ModuleNotFoundError: No module named 'oauth2client'

During handling of the above exception, another exception occurred:

Traceback (most recent call last):
  File "c:\users\user\appdata\local\programs\python\python37\lib\site-packages\googleapiclient\discovery_cache\__init__.py", line 44, in autodetect
    from . import file_cache
  File "c:\users\user\appdata\local\programs\python\python37\lib\site-packages\googleapiclient\discovery_cache\file_cache.py", line 41, in <module>
    "file_cache is unavailable when using oauth2client >= 4.0.0 or google-auth"
ImportError: file_cache is unavailable when using oauth2client >= 4.0.0 or google-auth
INFO:root:No upcoming events found.
INFO:werkzeug:127.0.0.1 - - [19/Apr/2021 11:31:47] "[37mGET /dashboard HTTP/1.1[0m" 200 -
WARNING:googleapiclient.discovery_cache:file_cache is unavailable when using oauth2client >= 4.0.0 or google-auth
Traceback (most recent call last):
  File "c:\users\user\appdata\local\programs\python\python37\lib\site-packages\googleapiclient\discovery_cache\file_cache.py", line 33, in <module>
    from oauth2client.contrib.locked_file import LockedFile
ModuleNotFoundError: No module named 'oauth2client'

During handling of the above exception, another exception occurred:

Traceback (most recent call last):
  File "c:\users\user\appdata\local\programs\python\python37\lib\site-packages\googleapiclient\discovery_cache\file_cache.py", line 37, in <module>
    from oauth2client.locked_file import LockedFile
ModuleNotFoundError: No module named 'oauth2client'

During handling of the above exception, another exception occurred:

Traceback (most recent call last):
  File "c:\users\user\appdata\local\programs\python\python37\lib\site-packages\googleapiclient\discovery_cache\__init__.py", line 44, in autodetect
    from . import file_cache
  File "c:\users\user\appdata\local\programs\python\python37\lib\site-packages\googleapiclient\discovery_cache\file_cache.py", line 41, in <module>
    "file_cache is unavailable when using oauth2client >= 4.0.0 or google-auth"
ImportError: file_cache is unavailable when using oauth2client >= 4.0.0 or google-auth
INFO:root:No upcoming events found.
INFO:werkzeug:127.0.0.1 - - [19/Apr/2021 11:31:53] "[37mGET /dashboard HTTP/1.1[0m" 200 -
INFO:werkzeug:127.0.0.1 - - [19/Apr/2021 11:31:53] "[37mGET /static/sms4_43518.ico HTTP/1.1[0m" 200 -
